Workbook

Sheet Въвеждане
A1: ТАЦ „Гранд“ — месечно разпределение на разходите за общите части
A2: По Методика, Приложение № 8 към Протокол от ОС на ЕС от 06.10.2026 г. Всички суми са в евро.
A3: Попълват се само жълтите клетки (син текст). Стойностите по-долу са ПРИМЕРНИ.
A5: Отчетен месец | B5: януари 2027 | C5: Текст
A7: 1. Постоянни текущи разходи (чл. 4, т. 1) | B7: 25000 | C7: Охрана, чистене, асансьори, заплати, счетоводство и др. Делят се поравно (чл. 5).
A8: 2. Вода (ВиК) за общите части (чл. 4, т. 2) | B8: 800 | C8: Делят се поравно между участващите обекти (чл. 6).
A9: 3. Електроенергия за общите части (чл. 4, т. 3) | B9: 6000 | C9: Дели се по идеални части без терасите (чл. 7).
A10: 4. Електроенергия за ОВК / чилъри (чл. 4, т. 4) | B10: 9000 | C10: Дели се по идеални части на обслужваните обекти от етажи 1–3 (чл. 8).
A12: Приходи от общите части за месеца (чл. 10) | B12: 3000 | C12: Реклама, LED екран, санитарни помещения, автомати и др.
A13: Каква част от приходите се приспада | B13: 1 | C13: 100% = основно правило (чл. 10, ал. 1). 0% или по-малко при изключенията по чл. 10, ал. 2.
A15: Изчисление
A16: Приспаднати приходи | B16: =B12*B13 -> 3000
A17: Постоянни разходи за разпределяне (след приходите) | B17: =B7-B16 -> 22000 | C17: Допускане: приходите се приспадат от постоянните разходи.
A19: Справка към собствениците (чл. 11)
A20: Перо | B20: Сума за разпределяне | C20: Брой / база | D20: Разпределено по обекти | E20: Проверка
A21: Постоянни разходи (поравно) | B21: =B17 -> 22000 | C21: =SUM(Обекти!H5:H261) -> 248 | D21: =SUM(Обекти!L5:L261) -> 22000 | E21: =IF(ABS(B21-D21)<0.01,"OK","ГРЕШКА") -> OK
A22: Вода общи части (поравно) | B22: =B8 -> 800 | C22: =SUM(Обекти!I5:I261) -> 246 | D22: =SUM(Обекти!M5:M261) -> 800 | E22: =IF(ABS(B22-D22)<0.01,"OK","ГРЕШКА") -> OK
A23: Ток общи части (по ид. части) | B23: =B9 -> 6000 | C23: =SUMPRODUCT(Обекти!C5:C261,Обекти!J5:J261) -> 89.529 | D23: =SUM(Обекти!N5:N261) -> 6000 | E23: =IF(ABS(B23-D23)<0.01,"OK","ГРЕШКА") -> OK
A24: Ток чилъри (по ид. части) | B24: =B10 -> 9000 | C24: =SUMPRODUCT(Обекти!C5:C261,Обекти!K5:K261) -> 39.512 | D24: =SUM(Обекти!O5:O261) -> 9000 | E24: =IF(ABS(B24-D24)<0.01,"OK","ГРЕШКА") -> OK
A25: ОБЩО | B25: =SUM(B21:B24) -> 37800 | D25: =SUM(Обекти!P5:P261) -> 37800 | E25: =IF(ABS(B25-D25)<0.01,"OK","ГРЕШКА") -> OK
A26: Колона „Брой / база“: за поравните пера е броят участващи обекти, за пропорционалните е сборът на идеалните им части (%).
A28: Допускания, които трябва да потвърди управителят
A29: • Хипермаркетът е обект „ЛЕКСИ“.
A30: • Всеки ред от списъка (вкл. 2-23-1 и 2-23-2 и т.н.) е отделен обект при поравното деление.
A31: • Обекти 1-70 и 1-71 (0% ид. части) участват в поравните пера.
A32: • „Обща тераса“ се третира като тераса и не плаща.
A33: • Към чилърите са свързани всички обекти на етажи 1–3. Дискотека-КА1 и Кафе -2.25 НЕ са свързани; ПИБ и Фреш бар СА свързани.
A34: • Дискотека-КА1, Кафе -2.25, ПИБ и Фреш бар участват във водата (фасада).
A35: • Всичко това се сменя в лист „Обекти“, колони H–K (1 = участва, 0 = не участва).

Sheet Обекти
A1: Обекти и разпределение
A2: Колони H–K (жълти) са отметки: 1 = участва, 0 = не участва. Попълнени са по методиката; сменят се при нужда. Колони L–P се смятат сами.
A4: № | B4: Обект | C4: Ид. част % | D4: Вид | E4: Етаж | F4: Бележка | H4: Участва: постоянни | I4: Участва: вода | J4: Участва: ток общи | K4: Участва: чилъри | L4: Постоянни € | M4: Вода € | N4: Ток общи € | O4: Чилъри € | P4: ОБЩО €
A5: 1 | B5: ГАРАЖ | C5: 19.588 | D5: гараж | E5: -1 | H5: 1 | I5: 0 | J5: 1 | K5: 0 | L5: =IF(H5=1,Въвеждане!$B$17/SUM($H$5:$H$261),0) -> 88.709677 | M5: =IF(I5=1,Въвеждане!$B$8/SUM($I$5:$I$261),0) -> 0 | N5: =IF(J5=1,Въвеждане!$B$9*C5/SUMPRODUCT($C$5:$C$261,$J$5:$J$261),0) -> 1312.7367 | O5: =IF(K5=1,Въвеждане!$B$10*C5/SUMPRODUCT($C$5:$C$261,$K$5:$K$261),0) -> 0 | P5: =SUM(L5:O5) -> 1401.4463
A6: 2 | B6: Дискотека-КА1 | C6: 1.303 | D6: обект | E6: ? | F6: Етажът не е известен — провери | H6: 1 | I6: 1 | J6: 1 | K6: 0 | L6: =IF(H6=1,Въвеждане!$B$17/SUM($H$5:$H$261),0) -> 88.709677 | M6: =IF(I6=1,Въвеждане!$B$8/SUM($I$5:$I$261),0) -> 3.2520325 | N6: =IF(J6=1,Въвеждане!$B$9*C6/SUMPRODUCT($C$5:$C$261,$J$5:$J$261),0) -> 87.32366 | O6: =IF(K6=1,Въвеждане!$B$10*C6/SUMPRODUCT($C$5:$C$261,$K$5:$K$261),0) -> 0 | P6: =SUM(L6:O6) -> 179.28537
A7: 3 | B7: ЛЕКСИ | C7: 19.628 | D7: хипермаркет | E7: ? | F7: Допускане: хипермаркет | H7: 1 | I7: 0 | J7: 1 | K7: 0 | L7: =IF(H7=1,Въвеждане!$B$17/SUM($H$5:$H$261),0) -> 88.709677 | M7: =IF(I7=1,Въвеждане!$B$8/SUM($I$5:$I$261),0) -> 0 | N7: =IF(J7=1,Въвеждане!$B$9*C7/SUMPRODUCT($C$5:$C$261,$J$5:$J$261),0) -> 1315.4174 | O7: =IF(K7=1,Въвеждане!$B$10*C7/SUMPRODUCT($C$5:$C$261,$K$5:$K$261),0) -> 0 | P7: =SUM(L7:O7) -> 1404.127
A8: 4 | B8: Кафе -2.25 | C8: 0.498 | D8: обект | E8: ? | F8: Етажът не е известен — провери | H8: 1 | I8: 1 | J8: 1 | K8: 0 | L8: =IF(H8=1,Въвеждане!$B$17/SUM($H$5:$H$261),0) -> 88.709677 | M8: =IF(I8=1,Въвеждане!$B$8/SUM($I$5:$I$261),0) -> 3.2520325 | N8: =IF(J8=1,Въвеждане!$B$9*C8/SUMPRODUCT($C$5:$C$261,$J$5:$J$261),0) -> 33.374661 | O8: =IF(K8=1,Въвеждане!$B$10*C8/SUMPRODUCT($C$5:$C$261,$K$5:$K$261),0) -> 0 | P8: =SUM(L8:O8) -> 125.33637
A9: 5 | B9: 1-67 | C9: 0.637 | D9: обект | E9: 1 | H9: 1 | I9: 1 | J9: 1 | K9: 1 | L9: =IF(H9=1,Въвеждане!$B$17/SUM($H$5:$H$261),0) -> 88.709677 | M9: =IF(I9=1,Въвеждане!$B$8/SUM($I$5:$I$261),0) -> 3.2520325 | N9: =IF(J9=1,Въвеждане!$B$9*C9/SUMPRODUCT($C$5:$C$261,$J$5:$J$261),0) -> 42.690078 | O9: =IF(K9=1,Въвеждане!$B$10*C9/SUMPRODUCT($C$5:$C$261,$K$5:$K$261),0) -> 145.09516 | P9: =SUM(L9:O9) -> 279.74695
A10: 6 | B10: 1-68 | C10: 0.239 | D10: обект | E10: 1 | H10: 1 | I10: 1 | J10: 1 | K10: 1 | L10: =IF(H10=1,Въвеждане!$B$17/SUM($H$5:$H$261),0) -> 88.709677 | M10: =IF(I10=1,Въвеждане!$B$8/SUM($I$5:$I$261),0) -> 3.2520325 | N10: =IF(J10=1,Въвеждане!$B$9*C10/SUMPRODUCT($C$5:$C$261,$J$5:$J$261),0) -> 16.017156 | O10: =IF(K10=1,Въвеждане!$B$10*C10/SUMPRODUCT($C$5:$C$261,$K$5:$K$261),0) -> 54.439158 | P10: =SUM(L10:O10) -> 162.41802
A11: 7 | B11: 1-69 Виваком | C11: 0.406 | D11: обект | E11: 1 | H11: 1 | I11: 1 | J11: 1 | K11: 1 | L11: =IF(H11=1,Въвеждане!$B$17/SUM($H$5:$H$261),0) -> 88.709677 | M11: =IF(I11=1,Въвеждане!$B$8/SUM($I$5:$I$261),0) -> 3.2520325 | N11: =IF(J11=1,Въвеждане!$B$9*C11/SUMPRODUCT($C$5:$C$261,$J$5:$J$261),0) -> 27.209061 | O11: =IF(K11=1,Въвеждане!$B$10*C11/SUMPRODUCT($C$5:$C$261,$K$5:$K$261),0) -> 92.478234 | P11: =SUM(L11:O11) -> 211.64901
A12: 8 | B12: ПИБ | C12: 1.827 | D12: обект | E12: ? | F12: Етажът не е известен — провери | H12: 1 | I12: 1 | J12: 1 | K12: 1 | L12: =IF(H12=1,Въвеждане!$B$17/SUM($H$5:$H$261),0) -> 88.709677 | M12: =IF(I12=1,Въвеждане!$B$8/SUM($I$5:$I$261),0) -> 3.2520325 | N12: =IF(J12=1,Въвеждане!$B$9*C12/SUMPRODUCT($C$5:$C$261,$J$5:$J$261),0) -> 122.44077 | O12: =IF(K12=1,Въвеждане!$B$10*C12/SUMPRODUCT($C$5:$C$261,$K$5:$K$261),0) -> 416.15206 | P12: =SUM(L12:O12) -> 630.55454
A13: 9 | B13: ФРЕШ БАР | C13: 0.28 | D13: обект | E13: ? | F13: Етажът не е известен — провери | H13: 1 | I13: 1 | J13: 1 | K13: 1 | L13: =IF(H13=1,Въвеждане!$B$17/SUM($H$5:$H$261),0) -> 88.709677 | M13: =IF(I13=1,Въвеждане!$B$8/SUM($I$5:$I$261),0) -> 3.2520325 | N13: =IF(J13=1,Въвеждане!$B$9*C13/SUMPRODUCT($C$5:$C$261,$J$5:$J$261),0) -> 18.764869 | O13: =IF(K13=1,Въвеждане!$B$10*C13/SUMPRODUCT($C$5:$C$261,$K$5:$K$261),0) -> 63.778093 | P13: =SUM(L13:O13) -> 174.50467
A14: 10 | B14: 1-1 | C14: 0.081 | D14: обект | E14: 1 | H14: 1 | I14: 1 | J14: 1 | K14: 1 | L14: =IF(H14=1,Въвеждане!$B$17/SUM($H$5:$H$261),0) -> 88.709677 | M14: =IF(I14=1,Въвеждане!$B$8/SUM($I$5:$I$261),0) -> 3.2520325 | N14: =IF(J14=1,Въвеждане!$B$9*C14/SUMPRODUCT($C$5:$C$261,$J$5:$J$261),0) -> 5.4284087 | O14: =IF(K14=1,Въвеждане!$B$10*C14/SUMPRODUCT($C$5:$C$261,$K$5:$K$261),0) -> 18.450091 | P14: =SUM(L14:O14) -> 115.84021
A15: 11 | B15: 1-2 | C15: 0.09 | D15: обект | E15: 1 | H15: 1 | I15: 1 | J15: 1 | K15: 1 | L15: =IF(H15=1,Въвеждане!$B$17/SUM($H$5:$H$261),0) -> 88.709677 | M15: =IF(I15=1,Въвеждане!$B$8/SUM($I$5:$I$261),0) -> 3.2520325 | N15: =IF(J15=1,Въвеждане!$B$9*C15/SUMPRODUCT($C$5:$C$261,$J$5:$J$261),0) -> 6.0315652 | O15: =IF(K15=1,Въвеждане!$B$10*C15/SUMPRODUCT($C$5:$C$261,$K$5:$K$261),0) -> 20.500101 | P15: =SUM(L15:O15) -> 118.49338
A16: 12 | B16: 1-3 | C16: 0.155 | D16: обект | E16: 1 | H16: 1 | I16: 1 | J16: 1 | K16: 1 | L16: =IF(H16=1,Въвеждане!$B$17/SUM($H$5:$H$261),0) -> 88.709677 | M16: =IF(I16=1,Въвеждане!$B$8/SUM($I$5:$I$261),0) -> 3.2520325 | N16: =IF(J16=1,Въвеждане!$B$9*C16/SUMPRODUCT($C$5:$C$261,$J$5:$J$261),0) -> 10.387696 | O16: =IF(K16=1,Въвеждане!$B$10*C16/SUMPRODUCT($C$5:$C$261,$K$5:$K$261),0) -> 35.30573 | P16: =SUM(L16:O16) -> 137.65514
A17: 13 | B17: 1-4 | C17: 0.167 | D17: обект | E17: 1 | H17: 1 | I17: 1 | J17: 1 | K17: 1 | L17: =IF(H17=1,Въвеждане!$B$17/SUM($H$5:$H$261),0) -> 88.709677 | M17: =IF(I17=1,Въвеждане!$B$8/SUM($I$5:$I$261),0) -> 3.2520325 | N17: =IF(J17=1,Въвеждане!$B$9*C17/SUMPRODUCT($C$5:$C$261,$J$5:$J$261),0) -> 11.191904 | O17: =IF(K17=1,Въвеждане!$B$10*C17/SUMPRODUCT($C$5:$C$261,$K$5:$K$261),0) -> 38.039077 | P17: =SUM(L17:O17) -> 141.19269
A18: 14 | B18: 1-5 | C18: 0.167 | D18: обект | E18: 1 | H18: 1 | I18: 1 | J18: 1 | K18: 1 | L18: =IF(H18=1,Въвеждане!$B$17/SUM($H$5:$H$261),0) -> 88.709677 | M18: =IF(I18=1,Въвеждане!$B$8/SUM($I$5:$I$261),0) -> 3.2520325 | N18: =IF(J18=1,Въвеждане!$B$9*C18/SUMPRODUCT($C$5:$C$261,$J$5:$J$261),0) -> 11.191904 | O18: =IF(K18=1,Въвеждане!$B$10*C18/SUMPRODUCT($C$5:$C$261,$K$5:$K$261),0) -> 38.039077 | P18: =SUM(L18:O18) -> 141.19269
A19: 15 | B19: 1-6 | C19: 0.155 | D19: обект | E19: 1 | H19: 1 | I19: 1 | J19: 1 | K19: 1 | L19: =IF(H19=1,Въвеждане!$B$17/SUM($H$5:$H$261),0) -> 88.709677 | M19: =IF(I19=1,Въвеждане!$B$8/SUM($I$5:$I$261),0) -> 3.2520325 | N19: =IF(J19=1,Въвеждане!$B$9*C19/SUMPRODUCT($C$5:$C$261,$J$5:$J$261),0) -> 10.387696 | O19: =IF(K19=1,Въвеждане!$B$10*C19/SUMPRODUCT($C$5:$C$261,$K$5:$K$261),0) -> 35.30573 | P19: =SUM(L19:O19) -> 137.65514
A20: 16 | B20: 1-7 | C20: 0.089 | D20: обект | E20: 1 | H20: 1 | I20: 1 | J20: 1 | K20: 1 | L20: =IF(H20=1,Въвеждане!$B$17/SUM($H$5:$H$261),0) -> 88.709677 | M20: =IF(I20=1,Въвеждане!$B$8/SUM($I$5:$I$261),0) -> 3.2520325 | N20: =IF(J20=1,Въвеждане!$B$9*C20/SUMPRODUCT($C$5:$C$261,$J$5:$J$261),0) -> 5.9645478 | O20: =IF(K20=1,Въвеждане!$B$10*C20/SUMPRODUCT($C$5:$C$261,$K$5:$K$261),0) -> 20.272322 | P20: =SUM(L20:O20) -> 118.19858
A21: 17 | B21: 1-8 | C21: 0.089 | D21: обект | E21: 1 | H21: 1 | I21: 1 | J21: 1 | K21: 1 | L21: =IF(H21=1,Въвеждане!$B$17/SUM($H$5:$H$261),0) -> 88.709677 | M21: =IF(I21=1,Въвеждане!$B$8/SUM($I$5:$I$261),0) -> 3.2520325 | N21: =IF(J21=1,Въвеждане!$B$9*C21/SUMPRODUCT($C$5:$C$261,$J$5:$J$261),0) -> 5.9645478 | O21: =IF(K21=1,Въвеждане!$B$10*C21/SUMPRODUCT($C$5:$C$261,$K$5:$K$261),0) -> 20.272322 | P21: =SUM(L21:O21) -> 118.19858
A22: 18 | B22: 1-9 | C22: 0.089 | D22: обект | E22: 1 | H22: 1 | I22: 1 | J22: 1 | K22: 1 | L22: =IF(H22=1,Въвеждане!$B$17/SUM($H$5:$H$261),0) -> 88.709677 | M22: =IF(I22=1,Въвеждане!$B$8/SUM($I$5:$I$261),0) -> 3.2520325 | N22: =IF(J22=1,Въвеждане!$B$9*C22/SUMPRODUCT($C$5:$C$261,$J$5:$J$261),0) -> 5.9645478 | O22: =IF(K22=1,Въвеждане!$B$10*C22/SUMPRODUCT($C$5:$C$261,$K$5:$K$261),0) -> 20.272322 | P22: =SUM(L22:O22) -> 118.19858
A23: 19 | B23: 1-10 | C23: 0.082 | D23: обект | E23: 1 | H23: 1 | I23: 1 | J23: 1 | K23: 1 | L23: =IF(H23=1,Въвеждане!$B$17/SUM($H$5:$H$261),0) -> 88.709677 | M23: =IF(I23=1,Въвеждане!$B$8/SUM($I$5:$I$261),0) -> 3.2520325 | N23: =IF(J23=1,Въвеждане!$B$9*C23/SUMPRODUCT($C$5:$C$261,$J$5:$J$261),0) -> 5.4954261 | O23: =IF(K23=1,Въвеждане!$B$10*C23/SUMPRODUCT($C$5:$C$261,$K$5:$K$261),0) -> 18.67787 | P23: =SUM(L23:O23) -> 116.13501
A24: 20 | B24: 1-11 | C24: 0.152 | D24: обект | E24: 1 | H24: 1 | I24: 1 | J24: 1 | K24: 1 | L24: =IF(H24=1,Въвеждане!$B$17/SUM($H$5:$H$261),0) -> 88.709677 | M24: =IF(I24=1,Въвеждане!$B$8/SUM($I$5:$I$261),0) -> 3.2520325 | N24: =IF(J24=1,Въвеждане!$B$9*C24/SUMPRODUCT($C$5:$C$261,$J$5:$J$261),0) -> 10.186643 | O24: =IF(K24=1,Въвеждане!$B$10*C24/SUMPRODUCT($C$5:$C$261,$K$5:$K$261),0) -> 34.622393 | P24: =SUM(L24:O24) -> 136.77075
A25: 21 | B25: 1-12 | C25: 0.092 | D25: обект | E25: 1 | H25: 1 | I25: 1 | J25: 1 | K25: 1 | L25: =IF(H25=1,Въвеждане!$B$17/SUM($H$5:$H$261),0) -> 88.709677 | M25: =IF(I25=1,Въвеждане!$B$8/SUM($I$5:$I$261),0) -> 3.2520325 | N25: =IF(J25=1,Въвеждане!$B$9*C25/SUMPRODUCT($C$5:$C$261,$J$5:$J$261),0) -> 6.1656 | O25: =IF(K25=1,Въвеждане!$B$10*C25/SUMPRODUCT($C$5:$C$261,$K$5:$K$261),0) -> 20.955659 | P25: =SUM(L25:O25) -> 119.08297
... A79: 75 | B79: 1-66 | C79: 0.323 | D79: обект | E79: 1 | H79: 1 | I79: 1 | J79: 1 | K79: 1 | L79: =IF(H79=1,Въвеждане!$B$17/SUM($H$5:$H$261),0) -> 88.709677 | M79: =IF(I79=1,Въвеждане!$B$8/SUM($I$5:$I$261),0) -> 3.2520325 | N79: =IF(J79=1,Въвеждане!$B$9*C79/SUMPRODUCT($C$5:$C$261,$J$5:$J$261),0) -> 21.646617 | O79: =IF(K79=1,Въвеждане!$B$10*C79/SUMPRODUCT($C$5:$C$261,$K$5:$K$261),0) -> 73.572586 | P79: =SUM(L79:O79) -> 187.18091
A80: 76 | B80: 1-70 | C80: 0 | D80: обект | E80: 1 | F80: 0% ид. части — провери участието | H80: 1 | I80: 1 | J80: 1 | K80: 1 | L80: =IF(H80=1,Въвеждане!$B$17/SUM($H$5:$H$261),0) -> 88.709677 | M80: =IF(I80=1,Въвеждане!$B$8/SUM($I$5:$I$261),0) -> 3.2520325 | N80: =IF(J80=1,Въвеждане!$B$9*C80/SUMPRODUCT($C$5:$C$261,$J$5:$J$261),0) -> 0 | O80: =IF(K80=1,Въвеждане!$B$10*C80/SUMPRODUCT($C$5:$C$261,$K$5:$K$261),0) -> 0 | P80: =SUM(L80:O80) -> 91.96171
A81: 77 | B81: 1-71 | C81: 0 | D81: обект | E81: 1 | F81: 0% ид. части — провери участието | H81: 1 | I81: 1 | J81: 1 | K81: 1 | L81: =IF(H81=1,Въвеждане!$B$17/SUM($H$5:$H$261),0) -> 88.709677 | M81: =IF(I81=1,Въвеждане!$B$8/SUM($I$5:$I$261),0) -> 3.2520325 | N81: =IF(J81=1,Въвеждане!$B$9*C81/SUMPRODUCT($C$5:$C$261,$J$5:$J$261),0) -> 0 | O81: =IF(K81=1,Въвеждане!$B$10*C81/SUMPRODUCT($C$5:$C$261,$K$5:$K$261),0) -> 0 | P81: =SUM(L81:O81) -> 91.96171
A82: 78 | B82: 2-1 | C82: 0.17 | D82: обект | E82: 2 | H82: 1 | I82: 1 | J82: 1 | K82: 1 | L82: =IF(H82=1,Въвеждане!$B$17/SUM($H$5:$H$261),0) -> 88.709677 | M82: =IF(I82=1,Въвеждане!$B$8/SUM($I$5:$I$261),0) -> 3.2520325 | N82: =IF(J82=1,Въвеждане!$B$9*C82/SUMPRODUCT($C$5:$C$261,$J$5:$J$261),0) -> 11.392956 | O82: =IF(K82=1,Въвеждане!$B$10*C82/SUMPRODUCT($C$5:$C$261,$K$5:$K$261),0) -> 38.722413 | P82: =SUM(L82:O82) -> 142.07708
A83: 79 | B83: 2-2 | C83: 0.165 | D83: обект | E83: 2 | H83: 1 | I83: 1 | J83: 1 | K83: 1 | L83: =IF(H83=1,Въвеждане!$B$17/SUM($H$5:$H$261),0) -> 88.709677 | M83: =IF(I83=1,Въвеждане!$B$8/SUM($I$5:$I$261),0) -> 3.2520325 | N83: =IF(J83=1,Въвеждане!$B$9*C83/SUMPRODUCT($C$5:$C$261,$J$5:$J$261),0) -> 11.05787 | O83: =IF(K83=1,Въвеждане!$B$10*C83/SUMPRODUCT($C$5:$C$261,$K$5:$K$261),0) -> 37.583519 | P83: =SUM(L83:O83) -> 140.6031
A84: 80 | B84: 2-3 | C84: 0.171 | D84: обект | E84: 2 | H84: 1 | I84: 1 | J84: 1 | K84: 1 | L84: =IF(H84=1,Въвеждане!$B$17/SUM($H$5:$H$261),0) -> 88.709677 | M84: =IF(I84=1,Въвеждане!$B$8/SUM($I$5:$I$261),0) -> 3.2520325 | N84: =IF(J84=1,Въвеждане!$B$9*C84/SUMPRODUCT($C$5:$C$261,$J$5:$J$261),0) -> 11.459974 | O84: =IF(K84=1,Въвеждане!$B$10*C84/SUMPRODUCT($C$5:$C$261,$K$5:$K$261),0) -> 38.950192 | P84: =SUM(L84:O84) -> 142.37188
A85: 81 | B85: 2-4 | C85: 0.171 | D85: обект | E85: 2 | H85: 1 | I85: 1 | J85: 1 | K85: 1 | L85: =IF(H85=1,Въвеждане!$B$17/SUM($H$5:$H$261),0) -> 88.709677 | M85: =IF(I85=1,Въвеждане!$B$8/SUM($I$5:$I$261),0) -> 3.2520325 | N85: =IF(J85=1,Въвеждане!$B$9*C85/SUMPRODUCT($C$5:$C$261,$J$5:$J$261),0) -> 11.459974 | O85: =IF(K85=1,Въвеждане!$B$10*C85/SUMPRODUCT($C$5:$C$261,$K$5:$K$261),0) -> 38.950192 | P85: =SUM(L85:O85) -> 142.37188
A86: 82 | B86: 2-5 | C86: 0.165 | D86: обект | E86: 2 | H86: 1 | I86: 1 | J86: 1 | K86: 1 | L86: =IF(H86=1,Въвеждане!$B$17/SUM($H$5:$H$261),0) -> 88.709677 | M86: =IF(I86=1,Въвеждане!$B$8/SUM($I$5:$I$261),0) -> 3.2520325 | N86: =IF(J86=1,Въвеждане!$B$9*C86/SUMPRODUCT($C$5:$C$261,$J$5:$J$261),0) -> 11.05787 | O86: =IF(K86=1,Въвеждане!$B$10*C86/SUMPRODUCT($C$5:$C$261,$K$5:$K$261),0) -> 37.583519 | P86: =SUM(L86:O86) -> 140.6031
A87: 83 | B87: 2-6 | C87: 0.18 | D87: обект | E87: 2 | H87: 1 | I87: 1 | J87: 1 | K87: 1 | L87: =IF(H87=1,Въвеждане!$B$17/SUM($H$5:$H$261),0) -> 88.709677 | M87: =IF(I87=1,Въвеждане!$B$8/SUM($I$5:$I$261),0) -> 3.2520325 | N87: =IF(J87=1,Въвеждане!$B$9*C87/SUMPRODUCT($C$5:$C$261,$J$5:$J$261),0) -> 12.06313 | O87: =IF(K87=1,Въвеждане!$B$10*C87/SUMPRODUCT($C$5:$C$261,$K$5:$K$261),0) -> 41.000202 | P87: =SUM(L87:O87) -> 145.02504
A88: 84 | B88: 2-7 | C88: 0.178 | D88: обект | E88: 2 | H88: 1 | I88: 1 | J88: 1 | K88: 1 | L88: =IF(H88=1,Въвеждане!$B$17/SUM($H$5:$H$261),0) -> 88.709677 | M88: =IF(I88=1,Въвеждане!$B$8/SUM($I$5:$I$261),0) -> 3.2520325 | N88: =IF(J88=1,Въвеждане!$B$9*C88/SUMPRODUCT($C$5:$C$261,$J$5:$J$261),0) -> 11.929096 | O88: =IF(K88=1,Въвеждане!$B$10*C88/SUMPRODUCT($C$5:$C$261,$K$5:$K$261),0) -> 40.544645 | P88: =SUM(L88:O88) -> 144.43545
A89: 85 | B89: 2-8 | C89: 0.163 | D89: обект | E89: 2 | H89: 1 | I89: 1 | J89: 1 | K89: 1 | L89: =IF(H89=1,Въвеждане!$B$17/SUM($H$5:$H$261),0) -> 88.709677 | M89: =IF(I89=1,Въвеждане!$B$8/SUM($I$5:$I$261),0) -> 3.2520325 | N89: =IF(J89=1,Въвеждане!$B$9*C89/SUMPRODUCT($C$5:$C$261,$J$5:$J$261),0) -> 10.923835 | O89: =IF(K89=1,Въвеждане!$B$10*C89/SUMPRODUCT($C$5:$C$261,$K$5:$K$261),0) -> 37.127961 | P89: =SUM(L89:O89) -> 140.01351
A90: 86 | B90: 2-9 | C90: 0.174 | D90: обект | E90: 2 | H90: 1 | I90: 1 | J90: 1 | K90: 1 | L90: =IF(H90=1,Въвеждане!$B$17/SUM($H$5:$H$261),0) -> 88.709677 | M90: =IF(I90=1,Въвеждане!$B$8/SUM($I$5:$I$261),0) -> 3.2520325 | N90: =IF(J90=1,Въвеждане!$B$9*C90/SUMPRODUCT($C$5:$C$261,$J$5:$J$261),0) -> 11.661026 | O90: =IF(K90=1,Въвеждане!$B$10*C90/SUMPRODUCT($C$5:$C$261,$K$5:$K$261),0) -> 39.633529 | P90: =SUM(L90:O90) -> 143.25627
A91: 87 | B91: 2-10 | C91: 0.217 | D91: обект | E91: 2 | H91: 1 | I91: 1 | J91: 1 | K91: 1 | L91: =IF(H91=1,Въвеждане!$B$17/SUM($H$5:$H$261),0) -> 88.709677 | M91: =IF(I91=1,Въвеждане!$B$8/SUM($I$5:$I$261),0) -> 3.2520325 | N91: =IF(J91=1,Въвеждане!$B$9*C91/SUMPRODUCT($C$5:$C$261,$J$5:$J$261),0) -> 14.542774 | O91: =IF(K91=1,Въвеждане!$B$10*C91/SUMPRODUCT($C$5:$C$261,$K$5:$K$261),0) -> 49.428022 | P91: =SUM(L91:O91) -> 155.93251
A92: 88 | B92: 2-11 | C92: 0.168 | D92: обект | E92: 2 | H92: 1 | I92: 1 | J92: 1 | K92: 1 | L92: =IF(H92=1,Въвеждане!$B$17/SUM($H$5:$H$261),0) -> 88.709677 | M92: =IF(I92=1,Въвеждане!$B$8/SUM($I$5:$I$261),0) -> 3.2520325 | N92: =IF(J92=1,Въвеждане!$B$9*C92/SUMPRODUCT($C$5:$C$261,$J$5:$J$261),0) -> 11.258922 | O92: =IF(K92=1,Въвеждане!$B$10*C92/SUMPRODUCT($C$5:$C$261,$K$5:$K$261),0) -> 38.266856 | P92: =SUM(L92:O92) -> 141.48749
A93: 89 | B93: 2-12 | C93: 0.166 | D93: обект | E93: 2 | H93: 1 | I93: 1 | J93: 1 | K93: 1 | L93: =IF(H93=1,Въвеждане!$B$17/SUM($H$5:$H$261),0) -> 88.709677 | M93: =IF(I93=1,Въвеждане!$B$8/SUM($I$5:$I$261),0) -> 3.2520325 | N93: =IF(J93=1,Въвеждане!$B$9*C93/SUMPRODUCT($C$5:$C$261,$J$5:$J$261),0) -> 11.124887 | O93: =IF(K93=1,Въвеждане!$B$10*C93/SUMPRODUCT($C$5:$C$261,$K$5:$K$261),0) -> 37.811298 | P93: =SUM(L93:O93) -> 140.89789
... A261: 257 | B261: Обща тераса | C261: 8.261 | D261: тераса | E261: 4 | H261: 0 | I261: 0 | J261: 0 | K261: 0 | L261: =IF(H261=1,Въвеждане!$B$17/SUM($H$5:$H$261),0) -> 0 | M261: =IF(I261=1,Въвеждане!$B$8/SUM($I$5:$I$261),0) -> 0 | N261: =IF(J261=1,Въвеждане!$B$9*C261/SUMPRODUCT($C$5:$C$261,$J$5:$J$261),0) -> 0 | O261: =IF(K261=1,Въвеждане!$B$10*C261/SUMPRODUCT($C$5:$C$261,$K$5:$K$261),0) -> 0 | P261: =SUM(L261:O261) -> 0
...

Sheet Бележка
A1: ТАЦ „Гранд“ — гр. Пловдив, ул. „Капитан Райчо“ № 56
A2: Месечна бележка за разходите за управление и поддръжка на общите части
A4: Отчетен месец: | B4: =Въвеждане!B5 -> януари 2027
A5: Обект (избери от списъка): | B5: 1-1
A6: Идеална част %: | B6: =INDEX(Обекти!C5:C261,MATCH(B5,Обекти!B5:B261,0)) -> 0.081
A8: 1. Равен дял от постоянните разходи | B8: =INDEX(Обекти!L5:L261,MATCH($B$5,Обекти!$B$5:$B$261,0)) -> 88.709677
A9: 2. Равен дял от водата за общите части | B9: =INDEX(Обекти!M5:M261,MATCH($B$5,Обекти!$B$5:$B$261,0)) -> 3.2520325
A10: 3. Дял от електроенергията за общите части | B10: =INDEX(Обекти!N5:N261,MATCH($B$5,Обекти!$B$5:$B$261,0)) -> 5.4284087
A11: 4. Дял от електроенергията за чилърите | B11: =INDEX(Обекти!O5:O261,MATCH($B$5,Обекти!$B$5:$B$261,0)) -> 18.450091
A12: ОБЩО ЗА ПЛАЩАНЕ | B12: =SUM(B8:B11) -> 115.84021
A14: Общи суми за месеца (чл. 11):
A15: Постоянни разходи | B15: =Въвеждане!B7 -> 25000
A16: Вода общи части | B16: =Въвеждане!B8 -> 800
A17: Ток общи части | B17: =Въвеждане!B9 -> 6000
A18: Ток чилъри | B18: =Въвеждане!B10 -> 9000
A19: Приходи от общите части | B19: =Въвеждане!B12 -> 3000
A20: от тях приспаднати | B20: =Въвеждане!B16 -> 3000
